package leo.me.la.domain

import kotlinx.coroutines.CancellationException

inline fun <R> resultOf(block: () -> R): Result<R> {
    return try {
        Result.success(block())
    } catch (e: CancellationException) {
        throw e
    } catch (e: Exception) {
        Result.failure(e)
    }
}

/**
 * Like [runCatching], but with proper coroutines cancellation handling. Also only catches [Exception] instead of [Throwable].
 *
 * Cancellation exceptions need to be rethrown. See https://github.com/Kotlin/kotlinx.coroutines/issues/1814.
 */
inline fun <T, R> T.resultOf(block: T.() -> R): Result<R> {
    return try {
        Result.success(block())
    } catch (e: CancellationException) {
        throw e
    } catch (e: Exception) {
        Result.failure(e)
    }
}
